I'm sorry, but an uncaught exception occurred.

While running game code:
  File "game/script.rpy", line 33, in script call
    call round_3
  File "game/questionaire.rpy", line 21, in script
    $ stats = generate_stats()
  File "game/questionaire.rpy", line 21, in <module>
    $ stats = generate_stats()
  File "game/script.rpy", line 22, in generate_stats
    "hp": random.randrange(1, 20, 1),
NameError: global name 'random' is not defined

-- Full Traceback ------------------------------------------------------------

Full traceback:
  File "game/script.rpy", line 33, in script call
    call round_3
  File "game/questionaire.rpy", line 21, in script
    $ stats = generate_stats()
  File "C:\Users\piano\Downloads\renpy-7.4.11-sdk/renpy/ast.py", line 928, in execute
    renpy.python.py_exec_bytecode(self.code.bytecode, self.hide, store=self.store)
  File "C:\Users\piano\Downloads\renpy-7.4.11-sdk/renpy/python.py", line 2245, in py_exec_bytecode
    exec(bytecode, globals, locals)
  File "game/questionaire.rpy", line 21, in <module>
    $ stats = generate_stats()
  File "game/script.rpy", line 22, in generate_stats
    "hp": random.randrange(1, 20, 1),
NameError: global name 'random' is not defined

Windows-10-10.0.19041
Ren'Py 7.4.11.2266
The Serum 1.0
Mon Dec 20 17:23:30 2021
